<?xml version="1.0"?>
<robot name="planesil" xmlns:xacro="http://www.ros.org/wiki/xacro">
    <xacro:include filename="$(find planesim_description)/urdf/materials.xacro" />
    <xacro:include filename="$(find planesim_description)/urdf/macros.xacro" />

    <!-- Body of plane -->
    <!-- <link name="body">
        <inertial>
            <origin xyz="-0.0414 0 0.9271" rpy="0 0 0"/>
            <mass value="680.389"/>
            <inertia ixx="1285.315427874" ixy="0.0" ixz="0.0" iyy="1824.930976707" iyz="0.0" izz="2666.893931043"/>
        </inertial>

        <collision>
            <origin xyz="0 0 0" rpy="0 0 0"/>
            <geometry>
                <mesh filename="package://planesim_description/meshes/body.dae"/>
            </geometry>
        </collision>

        <visual>
            <origin xyz="0 0 0" rpy="0 0 0"/>
            <geometry>
                <mesh filename="package://planesim_description/meshes/body.dae"/>
            </geometry>
            <material name="blue"/>
        </visual>
    </link> -->
    <xacro:property name="PI" value="3.14"/>

    <xacro:property name="bodyY" value="0.5"/>
    <xacro:property name="bodyX" value="8"/>
    <xacro:property name="bodyZ" value="0.5"/>
    <xacro:property name="bodyMass" value="300"/>

    <xacro:property name="wingY" value="5"/>
    <xacro:property name="wingX" value="1.5"/>
    <xacro:property name="wingZ" value="${bodyZ/4}"/>
    <xacro:property name="wingMass" value="100"/>

    <xacro:property name="wheelWidth" value="0.1"/>
    <xacro:property name="wheelRadius" value="0.5"/>
    <xacro:property name="wheelMass" value="5"/>

    <!-- X axis is down the runway -->


    <link name="body">
        <inertial>
            <origin xyz="0 0 0" rpy="0 0 0"/>
            <mass value="${bodyMass}"/>
            <xacro:box_inertia m="${bodyMass}" x="${bodyX}" y="${bodyY}" z="${bodyZ}"/>
        </inertial>

        <collision> 
            <origin xyz="0 0 0" rpy="0 0 0"/> 
            <geometry> 
                <box size="${bodyX} ${bodyY} ${bodyZ}"/> 
            </geometry> 
        </collision>

        <visual> 
            <origin xyz="0 0 0" rpy="0 0 0"/> 
            <geometry> 
                <box size="${bodyX} ${bodyY} ${bodyZ}"/> 
            </geometry> 
            <material name="orange"/>
        </visual>
    </link>

    <gazebo reference="body">
        <material>Gazebo/Orange</material>
    </gazebo>

    <link name="base_link"/>
    <joint name="base_joint" type="fixed">
        <parent link="base_link"/>
        <child link="body"/>
    </joint>

    <link name="leftWing">
        <inertial>
            <origin xyz="0 0 0" rpy="0 0 0"/> 
            <mass value="${wingMass}"/>
            <xacro:box_inertia m="${wingMass}" x="${wingX}" y="${wingY}" z="${wingZ}"/>
        </inertial>

        <collision> 
            <origin xyz="0 0 0" rpy="0 0 0"/>  
            <geometry> 
                <box size="${wingX} ${wingY} ${wingZ}"/> 
            </geometry> 
        </collision>

        <visual> 
            <origin xyz="0 0 0" rpy="0 0 0"/> 
            <geometry> 
                <box size="${wingX} ${wingY} ${wingZ}"/> 
            </geometry> 
            <material name="red"/>
        </visual>
    </link>

    <gazebo reference="leftWing">
        <material>
            Gazebo/Red
        </material>
    </gazebo>

    <joint name="leftWing_joint" type="continuous">
        <parent link="body"/>
        <child link="leftWing"/>
        <origin xyz="0 ${bodyY/2 + wingY/2} 0" rpy="0 0 0"/>
        <axis xyz="0 1 0" rpy="0 0 0"/>
    </joint>

    <link name="rightWing">
        <inertial>
            <origin xyz="0 0 0" rpy="0 0 0"/> 
            <mass value="${wingMass}"/>
            <xacro:box_inertia m="${wingMass}" x="${wingX}" y="${wingY}" z="${wingZ}"/>
        </inertial>

        <collision> 
            <origin xyz="0 0 0" rpy="0 0 0"/>  
            <geometry> 
                <box size="${wingX} ${wingY} ${wingZ}"/> 
            </geometry> 
        </collision>

        <visual> 
            <origin xyz="0 0 0" rpy="0 0 0"/> 
            <geometry> 
                <box size="${wingX} ${wingY} ${wingZ}"/> 
            </geometry> 
            <material name="green"/>
        </visual>
    </link>

    <gazebo reference="rightWing">
        <material>
            Gazebo/Green
        </material>
    </gazebo>

    <joint name="rightWing_joint" type="continuous">
        <parent link="body"/>
        <child link="rightWing"/>
        <origin xyz="0 ${-(bodyY/2 + wingY/2)} 0" rpy="0 0 0"/>
        <axis xyz="0 1 0" rpy="0 0 0"/>
    </joint>

    <xacro:wheel name="frontLeft_wheel" front="1" left="1" />
    <xacro:wheel name="frontRight_wheel" front="1" left="-1" />
    <xacro:wheel name="backLeft_wheel" front="-1" left="1" />
    <xacro:wheel name="backRight_wheel" front="-1" left="-1" />

    <gazebo>
        <plugin name="gazebo_ros_control" filename="libgazebo_ros_control.so">
            <robotNamespace>/planesim</robotNamespace>
        </plugin>
    </gazebo>

</robot>