<?xml version="1.0"?>
<robot name="planesil" xmlns:xacro="http://www.ros.org/wiki/xacro">
    <xacro:include filename="$(find planesim_description)/urdf/materials.xacro" />
    <xacro:include filename="$(find planesim_description)/urdf/macros.xacro" />

    <!-- Body of plane -->
    <link name="body">
        <inertial>
            <origin xyz="-0.0414 0 0.9271" rpy="0 0 0"/>
            <!-- <origin xyz="0 0 0" rpy="0 0 0"/> -->
            <mass value="680.389"/>
            <inertia ixx="1285.315427874" ixy="0.0" ixz="0.0" iyy="1824.930976707" iyz="0.0" izz="2666.893931043"/>
        </inertial>

        <collision>
            <origin xyz="0 0 0" rpy="0 0 0"/>
            <geometry>
                <mesh filename="package://planesim_description/meshes/body.dae"/>
            </geometry>
        </collision>

        <visual>
            <origin xyz="0 0 0" rpy="0 0 0"/>
            <geometry>
                <mesh filename="package://planesim_description/meshes/body.dae"/>
            </geometry>
            <material name="blue"/>
        </visual>
    </link>

    <link name='base_link'/>
    <joint name="base_joint" type="fixed">
        <parent link="base_link"/>
        <child link="body"/>
    </joint>

    <!-- Left aileron -->
    <link name="left_aileron">
        <inertial>
            <origin xyz="1.85 -3.7 -1.4" rpy="-0.05 -0 0.12" />
            <mass value="2"/>
            <inertia ixx="0.8434" ixy="0.0" ixz="0.0" iyy="0.0119" iyz="0.0" izz="0.855"/>
        </inertial>

        <collision>
            <origin xyz="1.85 -3.7 -1.4" rpy="-0.05 -0 0.12" />
            <geometry>
                <mesh filename="package://planesim_description/meshes/left_aileron.dae"/>
            </geometry>
        </collision>

        <visual>
            <origin xyz="1.85 -3.7 -1.4" rpy="-0.05 -0 0.12" />
            <geometry>
                <mesh filename="package://planesim_description/meshes/left_aileron.dae"/>
            </geometry>
            <material name="blue"/>
        </visual>
    </link>

    <joint name="left_aileron_joint" type="continuous">
        <parent link="body"/>
        <child link="left_aileron"/>
        <axis xyz="0 1 0" rpy="0 0 0"/>
        <origin xyz="-1.45 3.7 1.5" rpy="0.05 0 -0.12" />
        <limit lower="-0.5233" upper="0.5233" effort="100000" velocity="100000"/>
    </joint>

    <xacro:joint_transmission joint_name="left_aileron"/>
    
    <!-- Right aileron -->
    <link name="right_aileron">
        <inertial>
            <origin xyz="1.85 3.7 -1.4" rpy="0.05 -0 -0.12" />
            <mass value="2"/>
            <inertia ixx="0.8434" ixy="0.0" ixz="0.0" iyy="0.0119" iyz="0.0" izz="0.855"/>
        </inertial>

        <collision>
            <origin xyz="1.85 3.7 -1.4" rpy="0.05 -0 -0.12" />
            <geometry>
                <mesh filename="package://planesim_description/meshes/right_aileron.dae"/>
            </geometry>
        </collision>

        <visual>
            <origin xyz="1.85 3.7 -1.4" rpy="0.05 -0 -0.12" />
            <geometry>
                <mesh filename="package://planesim_description/meshes/right_aileron.dae"/>
            </geometry>
            <material name="blue"/>
        </visual>
    </link>

    <joint name="right_aileron_joint" type="continuous">
        <parent link="body"/>
        <child link="right_aileron"/>
        <axis xyz="0 1 0" rpy="0 0 0"/>
        <origin xyz="-1.45 -3.7 1.5" rpy="-0.05 0 0.12" />
        <limit lower="-0.5233" upper="0.5233" effort="100000" velocity="100000"/>
    </joint>

    <xacro:joint_transmission joint_name="right_aileron"/>


    <gazebo>
        <plugin name="gazebo_ros_control" filename="libgazebo_ros_control.so">
            <robotNamespace>/planesim</robotNamespace>
        </plugin>
    </gazebo>

</robot>